<?xml version='1.0' encoding='utf-8'?>
<robot name="T1">
  <link name="Trunk">
    <inertial>
      <origin xyz="0.0551365401093076 -1.42058017623659E-06 0.105062332707657" rpy="0 0 0" />
      <mass value="11.7" />
      <inertia ixx="0.0915287235057927" ixy="-4.25369739206781E-07" ixz="0.000646360369011163" iyy="0.076778716903413" iyz="5.82340020271393E-07" izz="0.0556171053368987" />
    </inertial>
    <visual>
      <origin xyz="0 0 0" rpy="0 0 0" />
      <geometry>
        <mesh filename="meshes/Trunk.STL" />
      </geometry>
      <material name="">
        <color rgba="0.76 0.76 0.76 0.2" />
      </material>
    </visual>
    <collision>
      <origin xyz="0.06 0 0.12" rpy="0 0 0" />
      <geometry>
        <box size="0.15 0.2 0.3" />
      </geometry>
    </collision>
  </link>
  <link name="H1">
    <inertial>
      <origin xyz="-0.000508 -0.001403 0.057432" rpy="0 0 0" />
      <mass value="0.443910" />
      <inertia ixx="0.000224" ixy="0.000003" ixz="0.000001" iyy="0.000241" iyz="-0.000002" izz="0.000150" />
    </inertial>
    <visual>
      <origin xyz="0 0 0" rpy="0 0 0" />
      <geometry>
        <mesh filename="meshes/H1.STL" />
      </geometry>
      <material name="">
        <color rgba="0.4 0.4 0.4 0.3" />
      </material>
    </visual>
  </link>
  <joint name="AAHead_yaw" type="revolute">
    <origin xyz="0.0625 0 0.243" rpy="0 0 0" />
    <parent link="Trunk" />
    <child link="H1" />
    <axis xyz="0 0 1" />
    <limit lower="-1.57" upper="1.57" effort="7" velocity="12.56" />
  </joint>
  <link name="H2">
    <inertial>
      <origin xyz="0.007802 0.001262 0.098631" rpy="0 0 0" />
      <mass value="0.631019" />
      <inertia ixx="0.002025" ixy="-0.000025" ixz="0.000046" iyy="0.001920" iyz="0.000036" izz="0.001739" />
    </inertial>
    <visual>
      <origin xyz="0 0 0" rpy="0 0 0" />
      <geometry>
        <mesh filename="meshes/H2.STL" />
      </geometry>
      <material name="">
        <color rgba="0.4 0.4 0.4 0.3" />
      </material>
    </visual>
    <collision>
      <origin xyz="0.01 0 0.11" rpy="0 0 0" />
      <geometry>
        <sphere radius="0.08" />
      </geometry>
    </collision>
  </link>
  <joint name="Head_pitch" type="revolute">
    <origin xyz="0 0 0.06185" rpy="0 0 0" />
    <parent link="H1" />
    <child link="H2" />
    <axis xyz="0 1 0" />
    <limit lower="-0.35" upper="1.22" effort="7" velocity="12.56" />
  </joint>
  <link name="Waist">
    <inertial>
      <origin xyz="0.002284 0.000003 0.007301" rpy="0 0 0" />
      <mass value="2.581" />
      <inertia ixx="0.005289" ixy="0.000000" ixz="0.000207" iyy="0.005299" iyz="0.000001" izz="0.004821" />
    </inertial>
    <visual>
      <origin xyz="0 0 0" rpy="0 0 0" />
      <geometry>
        <mesh filename="meshes/Waist.STL" />
      </geometry>
      <material name="">
        <color rgba="0.4 0.4 0.4 0.3" />
      </material>
    </visual>
  </link>
  <joint name="trunk_to_right_nero_base" type="fixed">
    <parent link="Trunk" />
    <child link="right_base_link" />
    <origin xyz="0.0575 -0.075 0.219" rpy="1.5707963267948966 -1.5707963267948966 0" />
  </joint>
  <joint name="trunk_to_left_nero_base" type="fixed">
    <parent link="Trunk" />
    <child link="left_base_link" />
    <origin xyz="0.0575 0.075 0.219" rpy="1.5707963267948966 -1.5707963267948966 3.141592653589793" />
  </joint>
  <link name="left_base_link">
    <inertial>
      <origin xyz="-0.00963614954335565 0.00016786624100977 0.044860101664403" rpy="0 0 0" />
      <mass value="0.77" />
      <inertia ixx="0.0006669" ixy="0.0" ixz="0.0" iyy="0.00054501" iyz="0.0" izz="0.00051509" />
    </inertial>
    <visual>
      <origin xyz="0 0 0" rpy="0 0 0" />
      <geometry>
        <mesh filename="/Users/jony/code/kimodo/pyroki/examples/nero_both_arms/meshes/dae/base_link.dae" />
      </geometry>
    </visual>
    <collision>
      <origin xyz="0 0 0" rpy="0 0 0" />
      <geometry>
        <mesh filename="/Users/jony/code/kimodo/pyroki/examples/nero_both_arms/meshes/base_link.STL" />
      </geometry>
    </collision>
  </link>
  <link name="left_link1">
    <inertial>
      <origin xyz="-0.00077 -0.00006 -0.00686" rpy="0 0 0" />
      <mass value="0.77" />
      <inertia ixx="0.0006669" ixy="0.0" ixz="0.0" iyy="0.00054501" iyz="0.0" izz="0.00051509" />
    </inertial>
    <visual>
      <origin xyz="0 0 0" rpy="0 0 0" />
      <geometry>
        <mesh filename="/Users/jony/code/kimodo/pyroki/examples/nero_both_arms/meshes/dae/link1.dae" />
      </geometry>
    </visual>
    <collision>
      <origin xyz="0 0 0" rpy="0 0 0" />
      <geometry>
        <mesh filename="/Users/jony/code/kimodo/pyroki/examples/nero_both_arms/meshes/Link1.STL" />
      </geometry>
    </collision>
  </link>
  <joint name="left_joint1" type="revolute">
    <origin xyz="0 0 0.138" rpy="0 0 0" />
    <parent link="left_base_link" />
    <child link="left_link1" />
    <axis xyz="0 0 1" />
    <limit lower="-2.7" upper="2.7" effort="0" velocity="0" />
  </joint>
  <link name="left_link2">
    <inertial>
      <origin xyz="-0.00011 -0.06072 0.00148" rpy="0 0 0" />
      <mass value="0.49" />
      <inertia ixx="0.00053808" ixy="0.0" ixz="0.0" iyy="0.00029435" iyz="0.0" izz="0.00040266" />
    </inertial>
    <visual>
      <origin xyz="0 0 0" rpy="0 0 0" />
      <geometry>
        <mesh filename="/Users/jony/code/kimodo/pyroki/examples/nero_both_arms/meshes/dae/link2.dae" />
      </geometry>
    </visual>
    <collision>
      <origin xyz="0 0 0" rpy="0 0 0" />
      <geometry>
        <mesh filename="/Users/jony/code/kimodo/pyroki/examples/nero_both_arms/meshes/Link2.STL" />
      </geometry>
    </collision>
  </link>
  <joint name="left_joint2" type="revolute">
    <origin xyz="0 0 0" rpy="1.5708 3.1415 0" />
    <parent link="left_link1" />
    <child link="left_link2" />
    <axis xyz="0 0 1" />
    <limit lower="-1.74" upper="1.74" effort="0" velocity="0" />
  </joint>
  <link name="left_link3">
    <inertial>
      <origin xyz="0.00014 0.00211 -0.04853" rpy="0 0 0" />
      <mass value="0.67" />
      <inertia ixx="0.00342528" ixy="0.0" ixz="0.0" iyy="0.0033924" iyz="0.0" izz="0.00026169" />
    </inertial>
    <visual>
      <origin xyz="0 0 0" rpy="0 0 0" />
      <geometry>
        <mesh filename="/Users/jony/code/kimodo/pyroki/examples/nero_both_arms/meshes/dae/link3.dae" />
      </geometry>
    </visual>
    <collision>
      <origin xyz="0 0 0" rpy="0 0 0" />
      <geometry>
        <mesh filename="/Users/jony/code/kimodo/pyroki/examples/nero_both_arms/meshes/Link3.STL" />
      </geometry>
    </collision>
  </link>
  <joint name="left_joint3" type="revolute">
    <origin xyz="0 -0.31 0" rpy="-1.5708 0 3.1416" />
    <parent link="left_link2" />
    <child link="left_link3" />
    <axis xyz="0 0 1" />
    <limit lower="-2.75" upper="2.75" effort="0" velocity="0" />
  </joint>
  <link name="left_link4">
    <inertial>
      <origin xyz="-0.00013 -0.05482 0.00132" rpy="0 0 0" />
      <mass value="0.41" />
      <inertia ixx="0.00031331" ixy="0.0" ixz="0.0" iyy="0.00013204" iyz="0.0" izz="0.0002393" />
    </inertial>
    <visual>
      <origin xyz="0 0 0" rpy="0 0 0" />
      <geometry>
        <mesh filename="/Users/jony/code/kimodo/pyroki/examples/nero_both_arms/meshes/dae/link4.dae" />
      </geometry>
    </visual>
    <collision>
      <origin xyz="0 0 0" rpy="0 0 0" />
      <geometry>
        <mesh filename="/Users/jony/code/kimodo/pyroki/examples/nero_both_arms/meshes/Link4.STL" />
      </geometry>
    </collision>
  </link>
  <joint name="left_joint4" type="revolute">
    <origin xyz="0 0 0" rpy="-1.5708 0 3.1416" />
    <parent link="left_link3" />
    <child link="left_link4" />
    <axis xyz="0 0 1" />
    <limit lower="-1.01" upper="2.14" effort="0" velocity="0" />
  </joint>
  <link name="left_link5">
    <inertial>
      <origin xyz="0.00303 0.00617 -0.11778" rpy="0 0 0" />
      <mass value="0.56" />
      <inertia ixx="0.0008249" ixy="0.0" ixz="0.0" iyy="0.00078548" iyz="0.0" izz="0.00021015" />
    </inertial>
    <visual>
      <origin xyz="0 0 0" rpy="0 0 0" />
      <geometry>
        <mesh filename="/Users/jony/code/kimodo/pyroki/examples/nero_both_arms/meshes/dae/link5.dae" />
      </geometry>
    </visual>
    <collision>
      <origin xyz="0 0 0" rpy="0 0 0" />
      <geometry>
        <mesh filename="/Users/jony/code/kimodo/pyroki/examples/nero_both_arms/meshes/Link5.STL" />
      </geometry>
    </collision>
  </link>
  <joint name="left_joint5" type="revolute">
    <origin xyz="0 -0.27001 0" rpy="1.5708 -1.5708 0" />
    <parent link="left_link4" />
    <child link="left_link5" />
    <axis xyz="0 0 1" />
    <limit lower="-2.75" upper="2.75" effort="0" velocity="0" />
  </joint>
  <link name="left_link6">
    <inertial>
      <origin xyz="0.00014 -0.0027 -0.00025" rpy="0 0 0" />
      <mass value="0.31" />
      <inertia ixx="0.00008181" ixy="0.0" ixz="0.0" iyy="0.00007176" iyz="0.0" izz="0.00007906" />
    </inertial>
    <visual>
      <origin xyz="0 0 0" rpy="0 0 0" />
      <geometry>
        <mesh filename="/Users/jony/code/kimodo/pyroki/examples/nero_both_arms/meshes/dae/link6.dae" />
      </geometry>
    </visual>
    <collision>
      <origin xyz="0 0 0" rpy="0 0 0" />
      <geometry>
        <mesh filename="/Users/jony/code/kimodo/pyroki/examples/nero_both_arms/meshes/Link6.STL" />
      </geometry>
    </collision>
  </link>
  <joint name="left_joint6" type="revolute">
    <origin xyz="0 0 0" rpy="1.5708 -1.5708 0" />
    <parent link="left_link5" />
    <child link="left_link6" />
    <axis xyz="0 0 1" />
    <limit lower="-0.73" upper="0.95" effort="0" velocity="0" />
  </joint>
  <link name="left_link7">
    <inertial>
      <origin xyz="-0.00014000 -0.00010000 -0.00275000" rpy="0 0 0" />
      <mass value="0.000001" />
      <inertia ixx="1.1000000000000001e-07" ixy="0" ixz="0" iyy="1.1000000000000001e-07" iyz="0" izz="1.9999999999999999e-07" />
    </inertial>
    <visual>
      <origin xyz="0 0 0" rpy="0 0 0" />
      <geometry>
        <mesh filename="/Users/jony/code/kimodo/pyroki/examples/nero_both_arms/meshes/dae/link7.dae" />
      </geometry>
    </visual>
    <collision>
      <origin xyz="0 0 0" rpy="0 0 0" />
      <geometry>
        <mesh filename="/Users/jony/code/kimodo/pyroki/examples/nero_both_arms/meshes/Link7.STL" />
      </geometry>
    </collision>
  </link>
  <joint name="left_joint7" type="revolute">
    <origin xyz="0 -0.0235 0" rpy="1.5708 0 0" />
    <parent link="left_link6" />
    <child link="left_link7" />
    <axis xyz="0 0 1" />
    <limit lower="-1.57" upper="1.57" effort="0" velocity="0" />
  </joint>
  <link name="left_link8">
    <inertial>
      <origin xyz="-0.01208 -0.00025 0.00032" rpy="0 0 0" />
      <mass value="0.05" />
      <inertia ixx="2.697e-05" ixy="0" ixz="0" iyy="4.311e-05" iyz="0" izz="2.479e-05" />
    </inertial>
    <visual>
      <origin xyz="0 0 0" rpy="-1.57 -1.57 -1.57" />
      <geometry>
        <mesh filename="/Users/jony/code/kimodo/pyroki/examples/nero_both_arms/meshes/stand_v1.dae" />
      </geometry>
    </visual>
    <collision>
      <origin xyz="0 0 0" rpy="-1.57 -1.57 -1.57" />
      <geometry>
        <mesh filename="/Users/jony/code/kimodo/pyroki/examples/nero_both_arms/meshes/stand_v1.dae" />
      </geometry>
    </collision>
  </link>
  <joint name="left_joint8" type="fixed">
    <origin xyz="0.033 0.00000000 -0.02350000" rpy="0 0 0" />
    <parent link="left_link7" />
    <child link="left_link8" />
  </joint>
  <link name="left_gripper_flange">
    <inertial>
      <origin xyz="0.0 0.0 -0.00032" rpy="0 0 0" />
      <mass value="0.04771096" />
      <inertia ixx="2.697e-05" ixy="0" ixz="0" iyy="4.311e-05" iyz="0" izz="2.479e-05" />
    </inertial>
    <visual>
      <origin xyz="0 0 0" rpy="0 0 0" />
      <geometry>
        <mesh filename="/Users/jony/code/kimodo/pyroki/examples/nero_both_arms/meshes/dae/gripper_flange.dae" />
      </geometry>
    </visual>
    <collision>
      <origin xyz="0 0 0" rpy="0 0 0" />
      <geometry>
        <mesh filename="/Users/jony/code/kimodo/pyroki/examples/nero_both_arms/meshes/gripper_flange.stl" />
      </geometry>
    </collision>
  </link>
  <joint name="left_gripper_flange_joint" type="fixed">
    <origin xyz="0.032 0 -0.0235" rpy="-1.5708 0 -1.5708" />
    <parent link="left_link7" />
    <child link="left_gripper_flange" />
  </joint>
  <link name="left_gripper_base">
    <inertial>
      <origin xyz="-0.000183807162235591 8.05033155577911E-05 0.0321436689908876" rpy="0 0 0" />
      <mass value="0.45" />
      <inertia ixx="0.00092934" ixy="0.00000034" ixz="-0.00000738" iyy="0.00071447" iyz="0.00000005" izz="0.00039442" />
    </inertial>
    <visual>
      <origin xyz="0 0 0" rpy="0 0 0" />
      <geometry>
        <mesh filename="/Users/jony/code/kimodo/pyroki/examples/nero_both_arms/meshes/dae/gripper_base.dae" />
      </geometry>
    </visual>
    <collision>
      <origin xyz="0 0 0" rpy="0 0 0" />
      <geometry>
        <mesh filename="/Users/jony/code/kimodo/pyroki/examples/nero_both_arms/meshes/gripper_base.stl" />
      </geometry>
    </collision>
  </link>
  <joint name="left_gripper_base_joint" type="fixed">
    <origin xyz="0 0 0.0055" rpy="0 0 0" />
    <parent link="left_gripper_flange" />
    <child link="left_gripper_base" />
  </joint>
  <link name="left_gripper_link1">
    <inertial>
      <origin xyz="0.00065123185041968 -0.0491929869131989 0.00972258769184025" rpy="0 0 0" />
      <mass value="0.025" />
      <inertia ixx="0.00007371" ixy="-0.00000113" ixz="0.00000021" iyy="0.00000781" iyz="-0.00001372" izz="0.0000747" />
    </inertial>
    <visual>
      <origin xyz="0 0 0" rpy="0 0 0" />
      <geometry>
        <mesh filename="/Users/jony/code/kimodo/pyroki/examples/nero_both_arms/meshes/dae/gripper_link1.dae" />
      </geometry>
    </visual>
    <collision>
      <origin xyz="0 0 0" rpy="0 0 0" />
      <geometry>
        <mesh filename="/Users/jony/code/kimodo/pyroki/examples/nero_both_arms/meshes/gripper_link1.stl" />
      </geometry>
    </collision>
  </link>
  <joint name="left_gripper_joint1" type="prismatic">
    <origin xyz="0 0 0.1358" rpy="1.5707963 0 3.1415926" />
    <parent link="left_gripper_base" />
    <child link="left_gripper_link1" />
    <axis xyz="0 0 1" />
    <limit lower="0" upper="0.05" effort="10" velocity="3" />
  </joint>
  <link name="left_gripper_link2">
    <inertial>
      <origin xyz="0.00065123185041968 -0.0491929869131989 0.00972258769184025" rpy="0 0 0" />
      <mass value="0.025" />
      <inertia ixx="0.00007371" ixy="-0.00000113" ixz="0.00000021" iyy="0.00000781" iyz="-0.00001372" izz="0.0000747" />
    </inertial>
    <visual>
      <origin xyz="0 0 0" rpy="0 0 0" />
      <geometry>
        <mesh filename="/Users/jony/code/kimodo/pyroki/examples/nero_both_arms/meshes/dae/gripper_link2.dae" />
      </geometry>
    </visual>
    <collision>
      <origin xyz="0 0 0" rpy="0 0 0" />
      <geometry>
        <mesh filename="/Users/jony/code/kimodo/pyroki/examples/nero_both_arms/meshes/gripper_link2.stl" />
      </geometry>
    </collision>
  </link>
  <joint name="left_gripper_joint2" type="prismatic">
    <origin xyz="0 0 0.1358" rpy="1.5707963 0 0" />
    <parent link="left_gripper_base" />
    <child link="left_gripper_link2" />
    <axis xyz="0 0 -1" />
    <limit lower="-0.05" upper="0" effort="10" velocity="3" />
  </joint>
  <link name="right_base_link">
    <inertial>
      <origin xyz="-0.00963614954335565 0.00016786624100977 0.044860101664403" rpy="0 0 0" />
      <mass value="0.77" />
      <inertia ixx="0.0006669" ixy="0.0" ixz="0.0" iyy="0.00054501" iyz="0.0" izz="0.00051509" />
    </inertial>
    <visual>
      <origin xyz="0 0 0" rpy="0 0 0" />
      <geometry>
        <mesh filename="/Users/jony/code/kimodo/pyroki/examples/nero_both_arms/meshes/dae/base_link.dae" />
      </geometry>
    </visual>
    <collision>
      <origin xyz="0 0 0" rpy="0 0 0" />
      <geometry>
        <mesh filename="/Users/jony/code/kimodo/pyroki/examples/nero_both_arms/meshes/base_link.STL" />
      </geometry>
    </collision>
  </link>
  <link name="right_link1">
    <inertial>
      <origin xyz="-0.00077 -0.00006 -0.00686" rpy="0 0 0" />
      <mass value="0.77" />
      <inertia ixx="0.0006669" ixy="0.0" ixz="0.0" iyy="0.00054501" iyz="0.0" izz="0.00051509" />
    </inertial>
    <visual>
      <origin xyz="0 0 0" rpy="0 0 0" />
      <geometry>
        <mesh filename="/Users/jony/code/kimodo/pyroki/examples/nero_both_arms/meshes/dae/link1.dae" />
      </geometry>
    </visual>
    <collision>
      <origin xyz="0 0 0" rpy="0 0 0" />
      <geometry>
        <mesh filename="/Users/jony/code/kimodo/pyroki/examples/nero_both_arms/meshes/Link1.STL" />
      </geometry>
    </collision>
  </link>
  <joint name="right_joint1" type="revolute">
    <origin xyz="0 0 0.138" rpy="0 0 0" />
    <parent link="right_base_link" />
    <child link="right_link1" />
    <axis xyz="0 0 1" />
    <limit lower="-2.7" upper="2.7" effort="0" velocity="0" />
  </joint>
  <link name="right_link2">
    <inertial>
      <origin xyz="-0.00011 -0.06072 0.00148" rpy="0 0 0" />
      <mass value="0.49" />
      <inertia ixx="0.00053808" ixy="0.0" ixz="0.0" iyy="0.00029435" iyz="0.0" izz="0.00040266" />
    </inertial>
    <visual>
      <origin xyz="0 0 0" rpy="0 0 0" />
      <geometry>
        <mesh filename="/Users/jony/code/kimodo/pyroki/examples/nero_both_arms/meshes/dae/link2.dae" />
      </geometry>
    </visual>
    <collision>
      <origin xyz="0 0 0" rpy="0 0 0" />
      <geometry>
        <mesh filename="/Users/jony/code/kimodo/pyroki/examples/nero_both_arms/meshes/Link2.STL" />
      </geometry>
    </collision>
  </link>
  <joint name="right_joint2" type="revolute">
    <origin xyz="0 0 0" rpy="1.5708 3.1415 0" />
    <parent link="right_link1" />
    <child link="right_link2" />
    <axis xyz="0 0 1" />
    <limit lower="-1.74" upper="1.74" effort="0" velocity="0" />
  </joint>
  <link name="right_link3">
    <inertial>
      <origin xyz="0.00014 0.00211 -0.04853" rpy="0 0 0" />
      <mass value="0.67" />
      <inertia ixx="0.00342528" ixy="0.0" ixz="0.0" iyy="0.0033924" iyz="0.0" izz="0.00026169" />
    </inertial>
    <visual>
      <origin xyz="0 0 0" rpy="0 0 0" />
      <geometry>
        <mesh filename="/Users/jony/code/kimodo/pyroki/examples/nero_both_arms/meshes/dae/link3.dae" />
      </geometry>
    </visual>
    <collision>
      <origin xyz="0 0 0" rpy="0 0 0" />
      <geometry>
        <mesh filename="/Users/jony/code/kimodo/pyroki/examples/nero_both_arms/meshes/Link3.STL" />
      </geometry>
    </collision>
  </link>
  <joint name="right_joint3" type="revolute">
    <origin xyz="0 -0.31 0" rpy="-1.5708 0 3.1416" />
    <parent link="right_link2" />
    <child link="right_link3" />
    <axis xyz="0 0 1" />
    <limit lower="-2.75" upper="2.75" effort="0" velocity="0" />
  </joint>
  <link name="right_link4">
    <inertial>
      <origin xyz="-0.00013 -0.05482 0.00132" rpy="0 0 0" />
      <mass value="0.41" />
      <inertia ixx="0.00031331" ixy="0.0" ixz="0.0" iyy="0.00013204" iyz="0.0" izz="0.0002393" />
    </inertial>
    <visual>
      <origin xyz="0 0 0" rpy="0 0 0" />
      <geometry>
        <mesh filename="/Users/jony/code/kimodo/pyroki/examples/nero_both_arms/meshes/dae/link4.dae" />
      </geometry>
    </visual>
    <collision>
      <origin xyz="0 0 0" rpy="0 0 0" />
      <geometry>
        <mesh filename="/Users/jony/code/kimodo/pyroki/examples/nero_both_arms/meshes/Link4.STL" />
      </geometry>
    </collision>
  </link>
  <joint name="right_joint4" type="revolute">
    <origin xyz="0 0 0" rpy="-1.5708 0 3.1416" />
    <parent link="right_link3" />
    <child link="right_link4" />
    <axis xyz="0 0 1" />
    <limit lower="-1.01" upper="2.14" effort="0" velocity="0" />
  </joint>
  <link name="right_link5">
    <inertial>
      <origin xyz="0.00303 0.00617 -0.11778" rpy="0 0 0" />
      <mass value="0.56" />
      <inertia ixx="0.0008249" ixy="0.0" ixz="0.0" iyy="0.00078548" iyz="0.0" izz="0.00021015" />
    </inertial>
    <visual>
      <origin xyz="0 0 0" rpy="0 0 0" />
      <geometry>
        <mesh filename="/Users/jony/code/kimodo/pyroki/examples/nero_both_arms/meshes/dae/link5.dae" />
      </geometry>
    </visual>
    <collision>
      <origin xyz="0 0 0" rpy="0 0 0" />
      <geometry>
        <mesh filename="/Users/jony/code/kimodo/pyroki/examples/nero_both_arms/meshes/Link5.STL" />
      </geometry>
    </collision>
  </link>
  <joint name="right_joint5" type="revolute">
    <origin xyz="0 -0.27001 0" rpy="1.5708 -1.5708 0" />
    <parent link="right_link4" />
    <child link="right_link5" />
    <axis xyz="0 0 1" />
    <limit lower="-2.75" upper="2.75" effort="0" velocity="0" />
  </joint>
  <link name="right_link6">
    <inertial>
      <origin xyz="0.00014 -0.0027 -0.00025" rpy="0 0 0" />
      <mass value="0.31" />
      <inertia ixx="0.00008181" ixy="0.0" ixz="0.0" iyy="0.00007176" iyz="0.0" izz="0.00007906" />
    </inertial>
    <visual>
      <origin xyz="0 0 0" rpy="0 0 0" />
      <geometry>
        <mesh filename="/Users/jony/code/kimodo/pyroki/examples/nero_both_arms/meshes/dae/link6.dae" />
      </geometry>
    </visual>
    <collision>
      <origin xyz="0 0 0" rpy="0 0 0" />
      <geometry>
        <mesh filename="/Users/jony/code/kimodo/pyroki/examples/nero_both_arms/meshes/Link6.STL" />
      </geometry>
    </collision>
  </link>
  <joint name="right_joint6" type="revolute">
    <origin xyz="0 0 0" rpy="1.5708 -1.5708 0" />
    <parent link="right_link5" />
    <child link="right_link6" />
    <axis xyz="0 0 1" />
    <limit lower="-0.73" upper="0.95" effort="0" velocity="0" />
  </joint>
  <link name="right_link7">
    <inertial>
      <origin xyz="-0.00014000 -0.00010000 -0.00275000" rpy="0 0 0" />
      <mass value="0.000001" />
      <inertia ixx="1.1000000000000001e-07" ixy="0" ixz="0" iyy="1.1000000000000001e-07" iyz="0" izz="1.9999999999999999e-07" />
    </inertial>
    <visual>
      <origin xyz="0 0 0" rpy="0 0 0" />
      <geometry>
        <mesh filename="/Users/jony/code/kimodo/pyroki/examples/nero_both_arms/meshes/dae/link7.dae" />
      </geometry>
    </visual>
    <collision>
      <origin xyz="0 0 0" rpy="0 0 0" />
      <geometry>
        <mesh filename="/Users/jony/code/kimodo/pyroki/examples/nero_both_arms/meshes/Link7.STL" />
      </geometry>
    </collision>
  </link>
  <joint name="right_joint7" type="revolute">
    <origin xyz="0 -0.0235 0" rpy="1.5708 0 0" />
    <parent link="right_link6" />
    <child link="right_link7" />
    <axis xyz="0 0 1" />
    <limit lower="-1.57" upper="1.57" effort="0" velocity="0" />
  </joint>
  <link name="right_link8">
    <inertial>
      <origin xyz="-0.01208 -0.00025 0.00032" rpy="0 0 0" />
      <mass value="0.05" />
      <inertia ixx="2.697e-05" ixy="0" ixz="0" iyy="4.311e-05" iyz="0" izz="2.479e-05" />
    </inertial>
    <visual>
      <origin xyz="0 0 0" rpy="-1.57 -1.57 -1.57" />
      <geometry>
        <mesh filename="/Users/jony/code/kimodo/pyroki/examples/nero_both_arms/meshes/stand_v1.dae" />
      </geometry>
    </visual>
    <collision>
      <origin xyz="0 0 0" rpy="-1.57 -1.57 -1.57" />
      <geometry>
        <mesh filename="/Users/jony/code/kimodo/pyroki/examples/nero_both_arms/meshes/stand_v1.dae" />
      </geometry>
    </collision>
  </link>
  <joint name="right_joint8" type="fixed">
    <origin xyz="0.033 0.00000000 -0.02350000" rpy="0 0 0" />
    <parent link="right_link7" />
    <child link="right_link8" />
  </joint>
  <link name="right_gripper_flange">
    <inertial>
      <origin xyz="0.0 0.0 -0.00032" rpy="0 0 0" />
      <mass value="0.04771096" />
      <inertia ixx="2.697e-05" ixy="0" ixz="0" iyy="4.311e-05" iyz="0" izz="2.479e-05" />
    </inertial>
    <visual>
      <origin xyz="0 0 0" rpy="0 0 0" />
      <geometry>
        <mesh filename="/Users/jony/code/kimodo/pyroki/examples/nero_both_arms/meshes/dae/gripper_flange.dae" />
      </geometry>
    </visual>
    <collision>
      <origin xyz="0 0 0" rpy="0 0 0" />
      <geometry>
        <mesh filename="/Users/jony/code/kimodo/pyroki/examples/nero_both_arms/meshes/gripper_flange.stl" />
      </geometry>
    </collision>
  </link>
  <joint name="right_gripper_flange_joint" type="fixed">
    <origin xyz="0.032 0 -0.0235" rpy="-1.5708 0 -1.5708" />
    <parent link="right_link7" />
    <child link="right_gripper_flange" />
  </joint>
  <link name="right_gripper_base">
    <inertial>
      <origin xyz="-0.000183807162235591 8.05033155577911E-05 0.0321436689908876" rpy="0 0 0" />
      <mass value="0.45" />
      <inertia ixx="0.00092934" ixy="0.00000034" ixz="-0.00000738" iyy="0.00071447" iyz="0.00000005" izz="0.00039442" />
    </inertial>
    <visual>
      <origin xyz="0 0 0" rpy="0 0 0" />
      <geometry>
        <mesh filename="/Users/jony/code/kimodo/pyroki/examples/nero_both_arms/meshes/dae/gripper_base.dae" />
      </geometry>
    </visual>
    <collision>
      <origin xyz="0 0 0" rpy="0 0 0" />
      <geometry>
        <mesh filename="/Users/jony/code/kimodo/pyroki/examples/nero_both_arms/meshes/gripper_base.stl" />
      </geometry>
    </collision>
  </link>
  <joint name="right_gripper_base_joint" type="fixed">
    <origin xyz="0 0 0.0055" rpy="0 0 0" />
    <parent link="right_gripper_flange" />
    <child link="right_gripper_base" />
  </joint>
  <link name="right_gripper_link1">
    <inertial>
      <origin xyz="0.00065123185041968 -0.0491929869131989 0.00972258769184025" rpy="0 0 0" />
      <mass value="0.025" />
      <inertia ixx="0.00007371" ixy="-0.00000113" ixz="0.00000021" iyy="0.00000781" iyz="-0.00001372" izz="0.0000747" />
    </inertial>
    <visual>
      <origin xyz="0 0 0" rpy="0 0 0" />
      <geometry>
        <mesh filename="/Users/jony/code/kimodo/pyroki/examples/nero_both_arms/meshes/dae/gripper_link1.dae" />
      </geometry>
    </visual>
    <collision>
      <origin xyz="0 0 0" rpy="0 0 0" />
      <geometry>
        <mesh filename="/Users/jony/code/kimodo/pyroki/examples/nero_both_arms/meshes/gripper_link1.stl" />
      </geometry>
    </collision>
  </link>
  <joint name="right_gripper_joint1" type="prismatic">
    <origin xyz="0 0 0.1358" rpy="1.5707963 0 3.1415926" />
    <parent link="right_gripper_base" />
    <child link="right_gripper_link1" />
    <axis xyz="0 0 1" />
    <limit lower="0" upper="0.05" effort="10" velocity="3" />
  </joint>
  <link name="right_gripper_link2">
    <inertial>
      <origin xyz="0.00065123185041968 -0.0491929869131989 0.00972258769184025" rpy="0 0 0" />
      <mass value="0.025" />
      <inertia ixx="0.00007371" ixy="-0.00000113" ixz="0.00000021" iyy="0.00000781" iyz="-0.00001372" izz="0.0000747" />
    </inertial>
    <visual>
      <origin xyz="0 0 0" rpy="0 0 0" />
      <geometry>
        <mesh filename="/Users/jony/code/kimodo/pyroki/examples/nero_both_arms/meshes/dae/gripper_link2.dae" />
      </geometry>
    </visual>
    <collision>
      <origin xyz="0 0 0" rpy="0 0 0" />
      <geometry>
        <mesh filename="/Users/jony/code/kimodo/pyroki/examples/nero_both_arms/meshes/gripper_link2.stl" />
      </geometry>
    </collision>
  </link>
  <joint name="right_gripper_joint2" type="prismatic">
    <origin xyz="0 0 0.1358" rpy="1.5707963 0 0" />
    <parent link="right_gripper_base" />
    <child link="right_gripper_link2" />
    <axis xyz="0 0 -1" />
    <limit lower="-0.05" upper="0" effort="10" velocity="3" />
  </joint>
  <joint name="Waist" type="revolute">
    <origin xyz="0.0625 0 -0.1155" rpy="0 0 0" />
    <parent link="Trunk" />
    <child link="Waist" />
    <axis xyz="0 0 1" />
    <limit lower="-1.57" upper="1.57" effort="30" velocity="10.88" />
  </joint>
  <link name="Hip_Pitch_Left">
    <inertial>
      <origin xyz="0.000534 -0.007296 -0.018083" rpy="0 0 0" />
      <mass value="1.021" />
      <inertia ixx="0.001805" ixy="0.000006" ixz="-0.000015" iyy="0.001421" iyz="0.000080" izz="0.001292" />
    </inertial>
    <visual>
      <origin xyz="0 0 0" rpy="0 0 0" />
      <geometry>
        <mesh filename="meshes/Hip_Pitch_Left.STL" />
      </geometry>
      <material name="">
        <color rgba="0.76 0.76 0.76 0.2" />
      </material>
    </visual>
  </link>
  <joint name="Left_Hip_Pitch" type="revolute">
    <origin xyz="0 0.106 0" rpy="0 0 0" />
    <parent link="Waist" />
    <child link="Hip_Pitch_Left" />
    <axis xyz="0 1 0" />
    <limit lower="-1.8" upper="1.57" effort="45" velocity="12.5" />
  </joint>
  <link name="Hip_Roll_Left">
    <inertial>
      <origin xyz="0.001101 0.000024 -0.053750" rpy="0 0 0" />
      <mass value="0.385" />
      <inertia ixx="0.001517" ixy="0.000000" ixz="0.000017" iyy="0.001743" iyz="0.000000" izz="0.000515" />
    </inertial>
    <visual>
      <origin xyz="0 0 0" rpy="0 0 0" />
      <geometry>
        <mesh filename="meshes/Hip_Roll_Left.STL" />
      </geometry>
      <material name="">
        <color rgba="0.4 0.4 0.4 0.3" />
      </material>
    </visual>
  </link>
  <joint name="Left_Hip_Roll" type="revolute">
    <origin xyz="0 0 -0.02" rpy="0 0 0" />
    <parent link="Hip_Pitch_Left" />
    <child link="Hip_Roll_Left" />
    <axis xyz="1 0 0" />
    <limit lower="-0.2" upper="1.57" effort="30" velocity="10.9" />
  </joint>
  <link name="Hip_Yaw_Left">
    <inertial>
      <origin xyz="-0.007233 0.000206 -0.089184" rpy="0 0 0" />
      <mass value="2.166" />
      <inertia ixx="0.025108" ixy="-0.000007" ixz="0.002094" iyy="0.025733" iyz="-0.000050" izz="0.002787" />
    </inertial>
    <visual>
      <origin xyz="0 0 0" rpy="0 0 0" />
      <geometry>
        <mesh filename="meshes/Hip_Yaw_Left.STL" />
      </geometry>
      <material name="">
        <color rgba="0.4 0.4 0.4 0.3" />
      </material>
    </visual>
    <collision>
      <origin xyz="0 0 0" rpy="0 0 0" />
      <geometry>
        <cylinder radius="0.05" length="0.16" />
      </geometry>
    </collision>
  </link>
  <joint name="Left_Hip_Yaw" type="revolute">
    <origin xyz="0 0 -0.081854" rpy="0 0 0" />
    <parent link="Hip_Roll_Left" />
    <child link="Hip_Yaw_Left" />
    <axis xyz="0 0 1" />
    <limit lower="-1" upper="1" effort="30" velocity="10.9" />
  </joint>
  <link name="Shank_Left">
    <inertial>
      <origin xyz="-0.006012 0.000259 -0.124318" rpy="0 0 0" />
      <mass value="1.73" />
      <inertia ixx="0.034618" ixy="0.000011" ixz="0.001561" iyy="0.034539" iyz="0.000197" izz="0.001934" />
    </inertial>
    <visual>
      <origin xyz="0 0 0" rpy="0 0 0" />
      <geometry>
        <mesh filename="meshes/Shank_Left.STL" />
      </geometry>
      <material name="">
        <color rgba="0.4 0.4 0.4 0.3" />
      </material>
    </visual>
    <collision>
      <origin xyz="0 0 -0.12" rpy="0 0 0" />
      <geometry>
        <cylinder radius="0.05" length="0.15" />
      </geometry>
    </collision>
  </link>
  <joint name="Left_Knee_Pitch" type="revolute">
    <origin xyz="-0.014 0 -0.134" rpy="0 0 0" />
    <parent link="Hip_Yaw_Left" />
    <child link="Shank_Left" />
    <axis xyz="0 1 0" />
    <limit lower="0" upper="2.34" effort="60" velocity="11.7" />
  </joint>
  <link name="Ankle_Cross_Left">
    <inertial>
      <origin xyz="-0.003722 0.000000 -0.007981" rpy="0 0 0" />
      <mass value="0.073" />
      <inertia ixx="0.000012" ixy="0.000000" ixz="0.000003" iyy="0.000029" iyz="0.000000" izz="0.000025" />
    </inertial>
    <visual>
      <origin xyz="0 0 0" rpy="0 0 0" />
      <geometry>
        <mesh filename="meshes/Ankle_Cross_Left.STL" />
      </geometry>
      <material name="">
        <color rgba="0.4 0.4 0.4 0.3" />
      </material>
    </visual>
  </link>
  <joint name="Left_Ankle_Pitch" type="revolute">
    <origin xyz="0 0 -0.28" rpy="0 0 0" />
    <parent link="Shank_Left" />
    <child link="Ankle_Cross_Left" />
    <axis xyz="0 1 0" />
    <limit lower="-0.87" upper="0.35" effort="20" velocity="18.8" />
  </joint>
  <link name="left_foot_link">
    <inertial>
      <origin xyz="-0.000249 0.000000 -0.009140" rpy="0 0 0" />
      <mass value="0.685" />
      <inertia ixx="0.002214" ixy="0" ixz="-0.000114" iyy="0.002385" iyz="0" izz="0.002671" />
    </inertial>
    <visual>
      <origin xyz="0 0 0" rpy="0 0 0" />
      <geometry>
        <mesh filename="meshes/left_foot_link.STL" />
      </geometry>
      <material name="">
        <color rgba="0.4 0.4 0.4 0.3" />
      </material>
    </visual>
    <collision>
      <origin xyz="0.01 0 -0.015" rpy="0 0 0" />
      <geometry>
        <box size="0.223 0.1 0.03" />
      </geometry>
    </collision>
  </link>
  <joint name="Left_Ankle_Roll" type="revolute">
    <origin xyz="0 0.00025 -0.012" rpy="0 0 0" />
    <parent link="Ankle_Cross_Left" />
    <child link="left_foot_link" />
    <axis xyz="1 0 0" />
    <limit lower="-0.44" upper="0.44" effort="15" velocity="12.4" />
  </joint>
  <link name="Hip_Pitch_Right">
    <inertial>
      <origin xyz="0.000534 0.007514 -0.018082" rpy="0 0 0" />
      <mass value="1.021" />
      <inertia ixx="0.001805" ixy="-0.000008" ixz="-0.000015" iyy="0.001421" iyz="-0.000085" izz="0.001292" />
    </inertial>
    <visual>
      <origin xyz="0 0 0" rpy="0 0 0" />
      <geometry>
        <mesh filename="meshes/Hip_Pitch_Right.STL" />
      </geometry>
      <material name="">
        <color rgba="0.76 0.76 0.76 0.2" />
      </material>
    </visual>
  </link>
  <joint name="Right_Hip_Pitch" type="revolute">
    <origin xyz="0 -0.106 0" rpy="0 0 0" />
    <parent link="Waist" />
    <child link="Hip_Pitch_Right" />
    <axis xyz="0 1 0" />
    <limit lower="-1.8" upper="1.57" effort="45" velocity="12.5" />
  </joint>
  <link name="Hip_Roll_Right">
    <inertial>
      <origin xyz="0.001099 0.000024 -0.053748" rpy="0 0 0" />
      <mass value="0.385" />
      <inertia ixx="0.001517" ixy="0.000000" ixz="0.000017" iyy="0.001743" iyz="0.000000" izz="0.000515" />
    </inertial>
    <visual>
      <origin xyz="0 0 0" rpy="0 0 0" />
      <geometry>
        <mesh filename="meshes/Hip_Roll_Right.STL" />
      </geometry>
      <material name="">
        <color rgba="0.4 0.4 0.4 0.3" />
      </material>
    </visual>
  </link>
  <joint name="Right_Hip_Roll" type="revolute">
    <origin xyz="0 0 -0.02" rpy="0 0 0" />
    <parent link="Hip_Pitch_Right" />
    <child link="Hip_Roll_Right" />
    <axis xyz="1 0 0" />
    <limit lower="-1.57" upper="0.2" effort="30" velocity="10.9" />
  </joint>
  <link name="Hip_Yaw_Right">
    <inertial>
      <origin xyz="-0.007191 -0.000149 -0.089220" rpy="0 0 0" />
      <mass value="2.17" />
      <inertia ixx="0.025137" ixy="0.000006" ixz="0.002086" iyy="0.025762" iyz="0.000044" izz="0.002787" />
    </inertial>
    <visual>
      <origin xyz="0 0 0" rpy="0 0 0" />
      <geometry>
        <mesh filename="meshes/Hip_Yaw_Right.STL" />
      </geometry>
      <material name="">
        <color rgba="0.4 0.4 0.4 0.3" />
      </material>
    </visual>
    <collision>
      <origin xyz="0 0 0" rpy="0 0 0" />
      <geometry>
        <cylinder radius="0.05" length="0.16" />
      </geometry>
    </collision>
  </link>
  <joint name="Right_Hip_Yaw" type="revolute">
    <origin xyz="0 0 -0.081854" rpy="0 0 0" />
    <parent link="Hip_Roll_Right" />
    <child link="Hip_Yaw_Right" />
    <axis xyz="0 0 1" />
    <limit lower="-1" upper="1" effort="30" velocity="10.9" />
  </joint>
  <link name="Shank_Right">
    <inertial>
      <origin xyz="-0.005741 -0.000541 -0.122602" rpy="0 0 0" />
      <mass value="1.79" />
      <inertia ixx="0.035098" ixy="-0.000009" ixz="0.001554" iyy="0.034958" iyz="-0.000086" izz="0.002039" />
    </inertial>
    <visual>
      <origin xyz="0 0 0" rpy="0 0 0" />
      <geometry>
        <mesh filename="meshes/Shank_Right.STL" />
      </geometry>
      <material name="">
        <color rgba="0.4 0.4 0.4 0.3" />
      </material>
    </visual>
    <collision>
      <origin xyz="0 0 -0.12" rpy="0 0 0" />
      <geometry>
        <cylinder radius="0.05" length="0.15" />
      </geometry>
    </collision>
  </link>
  <joint name="Right_Knee_Pitch" type="revolute">
    <origin xyz="-0.014 0 -0.134" rpy="0 0 0" />
    <parent link="Hip_Yaw_Right" />
    <child link="Shank_Right" />
    <axis xyz="0 1 0" />
    <limit lower="0" upper="2.34" effort="60" velocity="11.7" />
  </joint>
  <link name="Ankle_Cross_Right">
    <inertial>
      <origin xyz="-0.003722 0.000000 -0.007981" rpy="0 0 0" />
      <mass value="0.073" />
      <inertia ixx="0.000012" ixy="0.000000" ixz="0.000003" iyy="0.000029" iyz="0.000000" izz="0.000025" />
    </inertial>
    <visual>
      <origin xyz="0 0 0" rpy="0 0 0" />
      <geometry>
        <mesh filename="meshes/Ankle_Cross_Right.STL" />
      </geometry>
      <material name="">
        <color rgba="0.4 0.4 0.4 0.3" />
      </material>
    </visual>
  </link>
  <joint name="Right_Ankle_Pitch" type="revolute">
    <origin xyz="0 0 -0.28" rpy="0 0 0" />
    <parent link="Shank_Right" />
    <child link="Ankle_Cross_Right" />
    <axis xyz="0 1 0" />
    <limit lower="-0.87" upper="0.35" effort="20" velocity="18.8" />
  </joint>
  <link name="right_foot_link">
    <inertial>
      <origin xyz="-0.000248 0.000000 -0.009140" rpy="0 0 0" />
      <mass value="0.685" />
      <inertia ixx="0.002214" ixy="0" ixz="-0.000114" iyy="0.002385" iyz="0" izz="0.002671" />
    </inertial>
    <visual>
      <origin xyz="0 0 0" rpy="0 0 0" />
      <geometry>
        <mesh filename="meshes/right_foot_link.STL" />
      </geometry>
      <material name="">
        <color rgba="0.4 0.4 0.4 0.3" />
      </material>
    </visual>
    <collision>
      <origin xyz="0.01 0 -0.015" rpy="0 0 0" />
      <geometry>
        <box size="0.223 0.1 0.03" />
      </geometry>
    </collision>
  </link>
  <joint name="Right_Ankle_Roll" type="revolute">
    <origin xyz="0 -0.00025 -0.012" rpy="0 0 0" />
    <parent link="Ankle_Cross_Right" />
    <child link="right_foot_link" />
    <axis xyz="1 0 0" />
    <limit lower="-0.44" upper="0.44" effort="15" velocity="12.4" />
  </joint>
</robot>